Workbook
Name FIID: 'IGR XoL'!$B$18
Name FIID_Deductible: 'IGR XoL'!$D$18
Name FIID_Limit: 'IGR XoL'!$C$18
Name FUL: 'IGR XoL'!$B$19
Name FUL_Deductible: 'IGR XoL'!$D$19
Name FUL_Limit: 'IGR XoL'!$C$19
Name Generic_Defect_Loss: [1]Parameters!$C$5
Name Generic_Defect_Loss: Summary!$P$3
Name Proton_Flare_InsLoss: [1]Parameters!$C$11
Name Proton_Flare_InsLoss: Summary!$P$9
Name QUARTER: _xlfn.LAMBDA(_xlpm.date, YEAR(_xlpm.date) & "Q" & ROUNDUP((MONTH(_xlpm.date))/3,0))
Name QUARTER: _xlfn.LAMBDA(_xlpm.date, YEAR(_xlpm.date) & "Q" & ROUNDUP((MONTH(_xlpm.date))/3,0))
Name QUARTER: _xlfn.LAMBDA(_xlpm.date, YEAR(_xlpm.date) & "Q" & ROUNDUP((MONTH(_xlpm.date))/3,0))
Name QUARTER: _xlfn.LAMBDA(_xlpm.date, YEAR(_xlpm.date) & "Q" & ROUNDUP((MONTH(_xlpm.date))/3,0))
Name QUARTER: _xlfn.LAMBDA(_xlpm.date, YEAR(_xlpm.date) & "Q" & ROUNDUP((MONTH(_xlpm.date))/3,0))
Name RDS_date: #REF!
Name Space_Debris_Loss: [1]Parameters!$C$8
Name Space_Debris_Loss: Summary!$P$6

Sheet RDS QA
B4: The following must be present in each RDS and be completed such that each control is a 'pass'.
B7: RDS Name | C7: Space RDS Q2 2024
B9: Data Updated | C9: 45490
B10: QA Updated | C10: 45490
B13: Overall QA Status | C13: {=IF(AND(G18:G26="Passing"),"Passing","Failing")} -> Passing
B17: Area | C17: Item | D17: Control | E17: Response | F17: If No, reason RDS is still valid | G17: QA Status
B18: Data Quality | C18: Prequel Policy Listing | D18: Is volume of data provided consistent with last quarter? | E18: Y | G18: =IF(OR(E18="y",AND(E18="n",F18<>"")),"Passing","Failing") -> Passing
D19: Do numercial fields used in calcuation appear reasonable? (ie no blanks, minimum & maximum values and dates within expected range) | E19: N | F19: Manual risks input due to no Seradata ID and layers signed exposure manually entered for Inmarsat Fleet (highlighted in control tab) | G19: =IF(OR(E19="y",AND(E19="n",F19<>"")),"Passing","Failing") -> Passing
C20: Other Policy Listings (ie from MGA or Line slip, not Prequel) | D20: Is volume of data provided consistent with last quarter? | E20: Y | G20: =IF(OR(E20="y",AND(E20="n",F20<>"")),"Passing","Failing") -> Passing
D21: Do numercial fields used in calcuation appear reasonable? (ie no blanks, minimum & maximum values and dates within expected range) | E21: Y | G21: =IF(OR(E21="y",AND(E21="n",F21<>"")),"Passing","Failing") -> Passing
D22: Is volume of data provided consistent with EPI under contract? | E22: Y | G22: =IF(OR(E22="y",AND(E22="n",F22<>"")),"Passing","Failing") -> Passing
C23: IGR | D23: IGR values are the latest for the quarter-end reporting period | E23: Y | G23: =IF(OR(E23="y",AND(E23="n",F23<>"")),"Passing","Failing") -> Passing
B24: Narrative of Change | C24: Compare RDS results with Prior Quarter | D24: Provide short narrative explaining why RDS results from current quarter differ from last | F24: • FIID Proton Flare decreased by 16.5% this quarter due to 1 layer coming off risk with exposure 1,747,627 (intelsat 236131) and only 1 layer on risk this quarter with exposure 370,112. • FIID Space Weather decreased by 19% this quarter as 1 layer has become off risk with exposure 34,952,537 and 1 layer has become on risk with exposure 7,402,233 (telenor Thor). Max exposed bus is still SSL. • FIID Generic Defect dropped by 37% this quarter due to 1 layer off risk with exposure 3,495,254 and 1 layer coming on risk with exposure 1,480,447. Exposure dropped by 7,875,029 due to risk period factor dropping for 7 layers. • • FIID Space Debris dropped by 34% as 2 layers came off risk with exposure 6,033,437, 1 policy was cancelled (Airbus Defence and Space SASTheos – 2) with exposure 4,601,308 and 2 layers came on risk with exposure 4,709,422. • No changes to FIHL max risk. FIID and FIBL max risk dropped by 3% as last quarters Intelsat L+1 max risk layer is now off risk, this quarters max risk is another Intelsat L+1 layer on the same program with reduced exposure of 1,002,745. • No RIPs apply • RI recoveries are as follows: o 127,472,356 external QS with travellers o 311,082,653 QS ceded to FIBL o 47,924,982 XoL ceded to FIBL | G24: =IF(F24<>"","Passing","Failing") -> Passing
B25: Methodology Documentation | C25: Documented methodology used | D25: Confirm RDS calculation methodology used is as described in latest documentation | E25: Y | G25: =IF(OR(E25="y",AND(E25="n",F25<>"")),"Passing","Failing") -> Passing
B26: Version Control | C26: Confirm material changes to calculation spreadsheet have been noted | D26: Have any material changes to calculation spreadsheet been noted in "Control Tab"? | E26: Y | G26: =IF(OR(E26="y",AND(E26="n",F26<>"")),"Passing","Failing") -> Passing

Sheet Control
B4: User | C4: Date | D4: Tab | E4: Change
B5: SC | C5: 44756 | D5: Stored_Proc | E5: Changed column BA to look up IGR values from new table ("tbl_IGRCessionsToFIBL").
B6: SC | C6: 44756 | D6: Stored_Proc | E6: Changed column CC so that it uses IGR values from column BA rather than hardcoded values which may not be correct for certain policies
B7: SC | C7: 44756 | D7: Stored_Proc | E7: Changed columns CL & CS to use IGR values from column BA rather than hardcoded values
B8: CM | C8: 45295 | D8: IGR | E8: Updated IGR cessions
B9: CM | C9: 45295 | D9: tbl_IGRCessionsToFIBL | E9: Updated IGR cessions
B10: CM | C10: 45295 | D10: Stored_Proc | E10: Updated columns BA:BF, BK, BP, BW, CG, CP, CW for new IGR cessions
B11: CM | C11: 45295 | D11: SES Fleet | E11: Removed as SES fleet did not renew this year
B12: CM | C12: 45295 | D12: Summary | E12: Updated for new IGR Cessions
B13: CM | C13: 45295 | D13: Bus Manufacturer | E13: Updated for new IGR Cessions

Sheet Input Data
AO5: 1 | AP5: 2 | AQ5: 3 | AR5: 4 | AS5: 5 | AT5: 6 | AU5: 7 | AV5: 8
AN6: Outwards LayerID: | AO6: 59904 | AP6: 75074 | AQ6: 145877 | AR6: 236123 | AS6: 342090 | AT6: 383251 | AU6: 439174
AN7: Inception: | AO7: 43739 | AP7: 43983 | AQ7: 44105 | AR7: 44562 | AS7: 44927 | AT7: 45292 | AU7: 45658 | AV7: 46023
AN8: Expiry: | AO8: 43982 | AP8: 44104 | AQ8: 44561 | AR8: 44926 | AS8: 45291 | AT8: 45657 | AU8: 46022 | AV8: 46387
O9: Months before Expiry | P9: Risk Factor | AG9: {=(SUMPRODUCT('Input Data'!$AK:$AK,'Input Data'!$P:$P,--('Input Data'!$K:$K="GEO-GSO"),--('Input Data'!$Q:$Q=1),--('Input Data'!$AL:$AL="FIID"))+SUMPRODUCT('Input Data'!$AK:$AK,'Input Data'!$P:$P,--('Input Data'!$K:$K="MEO"),--('Input Data'!$Q:$Q=1),--('Input Data'!$AL:$AL="FIID")))*Generic_Defect_Loss} -> 40212326 | AN9: Type: | AO9: QS | AP9: QS | AQ9: QS | AR9: QS | AS9: QS | AT9: QS | AU9: QS | AV9: QS
O10: 0 | P10: 0.2 | AN10: Basis: | AO10: RAD | AP10: RAD | AQ10: RAD | AR10: RAD | AS10: RAD | AT10: RAD | AU10: RAD | AV10: RAD
C11: Manual adjustments - in line with Q4 results | O11: 6 | P11: 0.4 | AC11: Changed the formyula slightly - as it was allowing negative months left on risk - which causes error in column AC | AD11: Could set the prarams as named range | AE11: Added IF Error set to 0% - to avoid errors due to the nulls | AN11: QS Cede: | AO11: 0.1176471 | AP11: 0.038461 | AQ11: 0.2 | AR11: 0.2 | AS11: 0.2 | AT11: 0.2 | AU11: 0.2 | AV11: 0.2
O12: 12 | P12: 0.6 | AC12: =YEAR(AC15) -> 2026 | AN12: Limit: | AU12: NULL
O13: 18 | P13: 0.8 | AI13: {=(SUMPRODUCT('Input Data'!$AK:$AK,'Input Data'!$AE:$AE,--('Input Data'!$K:$K="GEO-GSO"),--('Input Data'!$Q:$Q=1))+SUMPRODUCT('Input Data'!$AK:$AK,'Input Data'!$AE:$AE,--('Input Data'!$K:$K="MEO"),--('Input Data'!$Q:$Q=1))+SUMPRODUCT('Input Data'!$AK:$AK,'Input Data'!$AE:$AE,--('Input Data'!$K:$K="LEO"),--('Input Data'!$Q:$Q=1)))*Space_Debris_Loss} -> 1.0877165e+08 | AN13: Attach: | AU13: NULL
O14: 999 | P14: 1 | AK14: what is S/C ? | AN14: Notes: | AO14: Space QS | AP14: Space QS | AQ14: External QS | AR14: External QS | AS14: External QS | AT14: External QS | AU14: External QS | AV14: External QS | BY14: =Proton_Flare_InsLoss -> 0.05 | CI14: =SUM(CI$20:CI$46) -> 9.523399e+08 | CJ14: =SUM(CJ$20:CJ$46) -> 5.940582e+08 | CK14: =SUM(CK$20:CK$46) -> 3.582817e+08 | CM14: =SUM(CM20:CM46) -> 4.7525484e+08 | CN14: =SUM(CN20:CN39) -> 0
P15: Added the iferror to set to zero for off risk date before the as at date - unless these lines are deleted? | Q15: Not in the SQL data input | R15: Not in the SQL data input - what is 'BH'? Berkshire Hathaway | S15: Set equal to 'Coverage' - seems to be 3 lines where this is NULL for the last 2 quarters | T15: Seems to be NULL for all - except for when the program type is 'NULL' in which case this is 'BOUND' | AB15: As At Date | AC15: 46113 | AH15: This factor could be parameterised - rather than hard coded Also would make more sense if calcs flow from left to right - so 'Signed Exposure' should be before this column. | AI15: This column is pasted values/hard coded - where is this coming from? - mostly 1 but the bottom but goes up in sequence? | AK15: =SUMPRODUCT(AK20:AK157,AE20:AE157) -> 88845985 | BC15: why does this one only includes column AN - whereas the formula in column AY includes column AO too? - both columns are zero | BO15: Inconsistent formula - BL uses col AK for entity and BM uses column U for entity - but both columns should be the same? | BT15: Sum by Layer. | BY15: Holding Co has all the risks | CC15: After QS & XoL | CD15: What is the 0.2 hard coded value? | CI15: =SUMIFS($AK:$AK,$Q:$Q,1,$K:$K,"GEO-GSO") -> 9.5413938e+08 | CJ15: =SUMIFS($AK:$AK,$Q:$Q,1,$K:$K,"GEO-GSO",$AL:$AL,CJ$19) -> 5.9585768e+08 | CK15: =SUMIFS($AK:$AK,$Q:$Q,1,$K:$K,"GEO-GSO",$AL:$AL,CK$19) -> 3.582817e+08 | CM15: Why is this only to line 39? | CN15: What is the 0.2 hard coded value? | CY15: Does not inlcude LEO - but per the process doc - it said LEO is included?
P16: Don't forget to change as at date | AK16: =AK17-[3]Stored_Proc!$AG$17 -> 1.7130134e+08 | AL16: =AK16*0.05 -> 8565066.8 | BY16: =SUM(BY20:BY134) -> 39350459 | BZ16: =SUM(BZ20:BZ134) -> 21554022 | CA16: =SUM(CA20:CA134) -> 17796437 | CB16: =SUM(CB20:CB134) -> 0 | CC16: =SUM(CC20:CC134) -> 25903983 | CD16: =SUM(CD20:CD134) -> 0 | CE16: only to 135? | CH16: Check | CI16: =ABS(SUM(CI$20:CI$46)-SUMIFS($AK:$AK,$Q:$Q,1,$K:$K,"GEO-GSO"))<1 -> FALSE | CJ16: =ABS(SUM(CJ$20:CJ$46)-SUMIFS($AK:$AK,$Q:$Q,1,$K:$K,"GEO-GSO",$AL:$AL,CJ$19))<1 -> FALSE | CK16: =ABS(SUM(CK$20:CK$46)-SUMIFS($AK:$AK,$Q:$Q,1,$K:$K,"GEO-GSO",$AL:$AL,CK$19))<1 -> TRUE | CR16: =SUM(CR20:CR161) -> 1.1996322e+08 | CS16: =SUM(CS20:CS161) -> 80221489 | CT16: =SUM(CT20:CT161) -> 39741734 | CU16: =SUM(CU20:CU161) -> 0 | CV16: =SUM(CV20:CV161) -> 73891218 | CW16: =SUM(CW20:CW161) -> 0 | CY16: =SUM(CY20:CY161) -> 43360438 | CZ16: =SUM(CZ20:CZ161) -> 25564001 | DA16: =SUM(DA20:DA161) -> 17796437 | DB16: =SUM(DB20:DB161) -> 0 | DC16: =SUM(DC20:DC161) -> 27908972 | DD16: =SUM(DD20:DD161) -> 0
P17: WARNING - Stored Proc not working on Risk Period Factor. Paste formula below into First cell then drag down | AA17: =SUM(AA20:AA955) -> 1.1068011e+09 | AJ17: =SUMIFS($AA:$AA,$K:$K,"GEO-GSO",$Q:$Q,1) -> 9.5413938e+08 | AK17: =SUMIFS(AA:AA,K:K,"geo-gso",Q:Q,1) -> 9.5413938e+08 | AY17: =SUM(AY20:AY188) -> 2.2136022e+08 | BF17: =SUM(BF20:BF753) -> 8.8544086e+08
A18: =B20&"_"&C20 | P18: =INDEX($O$10:$O$14,MATCH(DATEDIF($AB$15,L20,"M"),$N$10:$N$14,1)) | AC18: =IF(J20="LEO",ROUNDUP(((L20-$AB$15)/30.5),0)*P20,0) | AH18: Multiplying exposure by 12.5/30 to get Syndicate equity share | AO18: Ext RI | BE18: New 2026Q1 | BO18: FUL | BP18: FIID | BY18: Proton Flare | CI18: Space Weather | CR18: Generic Defect | CY18: Space Debris
B19: ProgramId | C19: LayerId | E19: Coverage | F19: MonthsOnRisk | G19: SpacecraftId | H19: Launch Date | I19: Inception | J19: Expiry | K19: Orbit Category | L19: On_Risk_Date | M19: Off_Risk_Date | N19: Bus Manufacturer | O19: Prime Manufacturer | P19: Risk_Period_Factor | Q19: On_Risk_Flag | R19: BH_Applicable | S19: Program_Type | T19: Underwriting_Status | U19: Program_Name | V19: Entity | W19: Mapping_Code | X19: Spacecraft Name | Y19: Bus Family | Z19: Vehicle Family | AA19: Layer Signed Exposure | AC19: Months left on risk | AD19: Risk Period Factor Space Debris | AF19: Is Consortium | AG19: Equity Share % | AH19: Equity Share USD | AI19: LayerID OCC | AJ19: Signed Exposure USD | AK19: Per S/C | AL19: Entity | AM19: UW Year | AO19: 1 | AP19: 2 | AQ19: 3 | AR19: 4 | AS19: 5 | AT19: 6 | AU19: 7 | AV19: 8 | AW19: 9 | AX19: 10 | AY19: External QS | AZ19: Ext RI | BB19: Net of External QS | BC19: Ext RI | BD19: Included in Inwards S3123 QS | BE19: Inward S3123 QS | BF19: Net of External QS & Ext RI | BG19: QS IGR | BH19: QS FIBL Ceded | BI19: Net of QS IGR | BJ19: XoL FIBL Ceded | BK19: Total FIBL Ceded | BL19: Net of XoL IGR | BN19: Max Manufacturer | BO19: Max Manufacturer To FUL | BP19: Max Manufacturer To FIID | BQ19: Max Manufacturer to FIBL | BR19: Max Manufacturer to BH | BT19: Max Risk (FIHL) | BU19: Max Risk | BV19: Max Risk To FIBL | BW19: Max Risk To BH | BY19: FIHL | BZ19: FUL | CA19: FIID | CB19: FIBL Direct | CC19: FIBL Ceded | CD19: BH | CI19: FIHL | CJ19: FUL | CK19: FIID | CL19: FIBL Direct | CM19: FIBL Ceded | CN19: BH | CR19: FIHL | CS19: FUL | CT19: FIID | CU19: FIBL Direct | CV19: FIBL Ceded | CW19: BH | CY19: FIHL | CZ19: FUL | DA19: FIID | DB19: FIBL Direct | DC19: FIBL Ceded | DD19: BH
A20: =B20&"_"&C20 -> 344664_1 | B20: 344664 | C20: 1 | D20: =IFERROR(MATCH(C20,'[4]Custom Earning Pattern Not Popu'!$B$5:$B$428,0),"NA") -> NA | E20: Orbit | F20: 12 | G20: 15153 | H20: 45011 | I20: 45839 | J20: 46203 | K20: GEO-GSO | L20: 45839 | M20: 46203 | N20: Astrium Satellites SAS (Toulouse) (Part of EADS) | O20: Airbus Defence and Space (Toulouse) | P20: =IFERROR(INDEX($P$10:$P$14,MATCH(DATEDIF($AC$15,M20,"M"),$O$10:$O$14,1)),0) -> 0.2 | Q20: 1 | R20: 0 | S20: =E20 -> Orbit | T20: NULL | U20: Arabsat | V20: FUL | W20: ASO | X20: Arabsat BADR 8 | Y20: EUROSTAR E3000 | Z20: NULL | AA20: 25242749 | AC20: =IF(IF(K20="LEO",ROUNDUP(((M20-$AC$15)/30.5),0)*Q20,0)<0,0,IF(K20="LEO",ROUNDUP(((M20-$AC$15)/30.5),0)*Q20,0)) -> 0 | AD20: {=IF(AC20=0,0,INDEX(Summary!$S$4:$S$7,MATCH(AC20,Summary!$R$4:$R$7)+1))} -> 0 | AE20: =IFERROR(INDEX(Summary!$Y$4:$Y$6,MATCH('Input Data'!K20,Summary!$U$4:$U$6,0)),0) -> 0.05 | AF20: =IF(I20>=DATE(2024,7,1),TRUE,FALSE) -> TRUE | AG20: =IF(AF20,INDEX('IG Equity Share'!$B:$B,MATCH(YEAR(I20),'IG Equity Share'!$A:$A,0)),0) -> 0.075 | AH20: =AJ20*AG20*_xlfn.XLOOKUP(I20,'S3123 Consortium Share'!$A$3:$A$5,'S3123 Consortium Share'!$F$3:$F$5,,-1) -> 788835.92 | AI20: 1 | AJ20: =AA20 -> 25242749 | AK20: =AJ20/AI20*Q20 -> 25242749 | AL20: =V20 -> FUL | AM20: =YEAR(I20) -> 2025 | AN20: =INDEX('[2]Input Data'!$AH:$AH,MATCH(A20,'[2]Input Data'!$A:$A,0),1)-AH20 -> 0 | AO20: =+IF(AND($I20<=AO$8,$I20>=AO$7),$AK20*AO$11,0) -> 0 | AP20: =+IF(AND($I20<=AP$8,$I20>=AP$7),$AK20*AP$11,0) -> 0 | AQ20: =+IF(AND($I20<=AQ$8,$I20>=AQ$7),$AK20*AQ$11,0) -> 0 | AR20: =+IF(AND($I20<=AR$8,$I20>=AR$7),$AK20*AR$11,0) -> 0 | AS20: =+IF(AND($I20<=AS$8,$I20>=AS$7),$AK20*AS$11,0) -> 0 | AT20: =+IF(AND($I20<=AT$8,$I20>=AT$7),$AK20*AT$11,0) -> 0 | AU20: =+IF(AND($I20<=AU$8,$I20>=AU$7),$AK20*AU$11,0) -> 5048549.9 | AV20: =+IF(AND($I20<=AV$8,$I20>=AV$7),$AK20*AV$11,0) -> 0 | AY20: =SUM(AO20:AX20) -> 5048549.9 | AZ20: =+AO20+AP20 -> 0 | BB20: =+AK20-AY20 -> 20194200 | BC20: =SUM(AO20) -> 0 | BD20: =AND(AF20,NOT(ISNUMBER(MATCH(G20,Table1[Excluded Spacecraft ID],0)))) -> TRUE | BE20: =BD20*AK20*_xlfn.XLOOKUP(I20,Table2[Date From],Table2[Cession],"Error",-1)*_xlfn.XLOOKUP(I20,'S3123 Consortium Share'!$A$3:$A$5,'S3123 Consortium Share'!$F$3:$F$5,,-1) -> 2103562.5 | BF20: =+BB20-BC20 -> 20194200 | BG20: {=IF(V20="FIBL",0,INDEX('IGR QS'!$A$1:$D$570,MATCH('Input Data'!V20&'Input Data'!W20&'Input Data'!AM20,'IGR QS'!A:A&'IGR QS'!B:B&'IGR QS'!C:C,0),4))} -> 0.5 | BH20: =+BF20*BG20 -> 10097100 | BI20: =+BF20-BH20 -> 10097100 | BJ20: =IF(AND(V20=FIID,(BI20>FIID_Deductible)),MIN(BI20-FIID_Deductible,FIID_Limit),IF(AND(V20=FUL,(BI20>FUL_Deductible)),MIN(BI20-FUL_Deductible,FUL_Limit),0)) -> 0 | BK20: =BH20+BJ20 -> 10097100 | BL20: =+BI20-BJ20 -> 10097100 | BN20: =SUMIFS($BL:$BL,$N:$N,$N20,$Q:$Q,1) -> 17510967 | BO20: =SUMIFS($BL:$BL,$N:$N,$N20,$Q:$Q,1,$AL:$AL,$BO$18) -> 14332947 | BP20: =SUMIFS($BL:$BL,$N:$N,$N20,$V:$V,BP$18) -> 3178019.9 | BQ20: =SUMIFS($BK:$BK,$N:$N,$N20) -> 32341726 | BR20: =SUMIFS($AY:$AY,$N:$N,$N20) -> 12463173 | BT20: =SUMIFS($BF:$BF,$C:$C,$C20) -> 42889947 | BU20: =SUMIFS($BL:$BL,$C:$C,$C20) -> 15281915 | BV20: =SUMIFS($BK:$BK,$C:$C,$C20) -> 27608031 | BW20: =SUMIFS($AY:$AY,$C:$C,$C20) -> 10722487 | BY20: =IF($K20="GEO-GSO",$AK20*Proton_Flare_InsLoss,0)*Q20 -> 1262137.5 | BZ20: =IF(AND($K20="GEO-GSO",AL20="FUL"),$AK20*Proton_Flare_InsLoss,0)*$Q20 -> 1262137.5 | CA20: =IF(AND($K20="GEO-GSO",AL20="FIID"),$AK20*Proton_Flare_InsLoss,0)*$Q20 -> 0 | CB20: =IF(AND($K20="GEO-GSO",AL20="FIBL"),$AK20*Proton_Flare_InsLoss,0)*$Q20 -> 0 | CC20: =IF($K20="GEO-GSO",(AK20*BG20-BJ20)*Proton_Flare_InsLoss,0)*Q20 -> 631068.74 | CD20: =IF($K20="GEO-GSO",$AK20*Proton_Flare_InsLoss,0)*$Q20*$R20*0.2 -> 0 | CH20: {=_xlfn.UNIQUE($N$20:$N701)} -> Astrium Satellites SAS (Toulouse) (Part of EADS) | CI20: =SUMIFS($AK:$AK,$K:$K,"GEO-GSO",$N:$N,$CH20,$Q:$Q,1) -> 62315867 | CJ20: =SUMIFS($AK:$AK,$K:$K,"GEO-GSO",$N:$N,$CH20,$Q:$Q,1,$AL:$AL,CJ$19) -> 35832368 | CK20: =SUMIFS($AK:$AK,$K:$K,"GEO-GSO",$N:$N,$CH20,$Q:$Q,1,$AL:$AL,CK$19) -> 26483499 | CL20: =SUMIFS($AK:$AK,$K:$K,"GEO-GSO",$N:$N,$CH20,$Q:$Q,1,$AL:$AL,"FIBL") -> 0 | CM20: =SUMIFS($BK:$BK,$K:$K,"GEO-GSO",$N:$N,CH20,$Q:$Q,1) -> 32341726 | CN20: =SUMIFS($AK:$AK,$K:$K,"GEO-GSO",$N:$N,$CH20,$Q:$Q,1,$R:$R,1)*0.2 -> 0 | CR20: =IF(OR($K20="GEO-GSO",$K20="MEO"),$AK20*Generic_Defect_Loss,0)*$Q20*$P20 -> 2524274.9 | CS20: =IF(AND(OR($K20="GEO-GSO",$K20="MEO"),$AL20=CS$19),$AK20*Generic_Defect_Loss,0)*$Q20*$P20 -> 2524274.9 | CT20: =IF(AND(OR($K20="GEO-GSO",$K20="MEO"),$AL20=CT$19),$AK20*Generic_Defect_Loss,0)*$Q20*$P20 -> 0 | CU20: =IF(AND(OR($K20="GEO-GSO",$K20="MEO"),$AL20="FIBL"),$AK20*Generic_Defect_Loss,0)*$Q20*$P20 -> 0 | CV20: =IF(OR($K20="GEO-GSO",$K20="MEO"),($AK20*BG20-BJ20)*Generic_Defect_Loss,0)*$Q20*$P20 -> 1262137.5 | CW20: =IF(OR($K20="GEO-GSO",$K20="MEO"),$AK20*Generic_Defect_Loss,0)*$Q20*$P20*$R20*0.2 -> 0 | CY20: =IF(OR($K20="GEO-GSO",$K20="MEO"),$AK20*Space_Debris_Loss,0)*$Q20*$AE20 -> 1262137.5 | CZ20: =IF(AND(OR($K20="GEO-GSO",$K20="MEO"),$AL20=CZ$19),$AK20*Space_Debris_Loss,0)*$Q20*$AE20 -> 1262137.5 | DA20: =IF(AND(OR($K20="GEO-GSO",$K20="MEO",$K20="LEO"),$AL20=DA$19),$AK20*Space_Debris_Loss,0)*$Q20*$AE20 -> 0 | DB20: =IF(AND(OR($K20="GEO-GSO",$K20="MEO"),$AL20="FIBL"),$AK20*Space_Debris_Loss,0)*$Q20*$AE20 -> 0 | DC20: =IF(OR($K20="GEO-GSO",$K20="MEO"),($AK20*BG20-BJ20)*Space_Debris_Loss,0)*$Q20*$AE20 -> 631068.74 | DD20: =IF(OR($K20="GEO-GSO",$K20="MEO"),$AK20*1,0)*$Q20*$AE20*$R20*0.2 -> 0
A21: =B21&"_"&C21 -> 344664_2 | B21: 344664 | C21: 2 | D21: =IFERROR(MATCH(C21,'[4]Custom Earning Pattern Not Popu'!$B$5:$B$428,0),"NA") -> NA | E21: Orbit | F21: 12 | G21: 8249 | H21: 43566 | I21: 45839 | J21: 45869 | K21: GEO-GSO | L21: 45839 | M21: 46203 | N21: Astrium Satellites SAS (Toulouse) (Part of EADS) | O21: Astrium Satellites SAS (Toulouse) (Part of EADS) | P21: =IFERROR(INDEX($P$10:$P$14,MATCH(DATEDIF($AC$15,M21,"M"),$O$10:$O$14,1)),0) -> 0.2 | Q21: 1 | R21: 0 | S21: =E21 -> Orbit | T21: NULL | U21: Arabsat | V21: FUL | W21: ASO | X21: Arabsat 5A | Y21: EUROSTAR E3000 | Z21: NULL | AA21: 102523.91 | AC21: =IF(IF(K21="LEO",ROUNDUP(((M21-$AC$15)/30.5),0)*Q21,0)<0,0,IF(K21="LEO",ROUNDUP(((M21-$AC$15)/30.5),0)*Q21,0)) -> 0 | AD21: {=IF(AC21=0,0,INDEX(Summary!$S$4:$S$7,MATCH(AC21,Summary!$R$4:$R$7)+1))} -> 0 | AE21: =IFERROR(INDEX(Summary!$Y$4:$Y$6,MATCH('Input Data'!K21,Summary!$U$4:$U$6,0)),0) -> 0.05 | AF21: =IF(I21>=DATE(2024,7,1),TRUE,FALSE) -> TRUE | AG21: =IF(AF21,INDEX('IG Equity Share'!$B:$B,MATCH(YEAR(I21),'IG Equity Share'!$A:$A,0)),0) -> 0.075 | AH21: =AJ21*AG21*_xlfn.XLOOKUP(I21,'S3123 Consortium Share'!$A$3:$A$5,'S3123 Consortium Share'!$F$3:$F$5,,-1) -> 3203.8723 | AI21: 1 | AJ21: =AA21 -> 102523.91 | AK21: =AJ21/AI21*Q21 -> 102523.91 | AL21: =V21 -> FUL | AM21: =YEAR(I21) -> 2025 | AO21: =+IF(AND($I21<=AO$8,$I21>=AO$7),$AK21*AO$11,0) -> 0 | AP21: =+IF(AND($I21<=AP$8,$I21>=AP$7),$AK21*AP$11,0) -> 0 | AQ21: =+IF(AND($I21<=AQ$8,$I21>=AQ$7),$AK21*AQ$11,0) -> 0 | AR21: =+IF(AND($I21<=AR$8,$I21>=AR$7),$AK21*AR$11,0) -> 0 | AS21: =+IF(AND($I21<=AS$8,$I21>=AS$7),$AK21*AS$11,0) -> 0 | AT21: =+IF(AND($I21<=AT$8,$I21>=AT$7),$AK21*AT$11,0) -> 0 | AU21: =+IF(AND($I21<=AU$8,$I21>=AU$7),$AK21*AU$11,0) -> 20504.783 | AV21: =+IF(AND($I21<=AV$8,$I21>=AV$7),$AK21*AV$11,0) -> 0 | AY21: =SUM(AO21:AX21) -> 20504.783 | AZ21: =+AO21+AP21 -> 0 | BB21: =+AK21-AY21 -> 82019.131 | BC21: =SUM(AO21) -> 0 | BD21: =AND(AF21,NOT(ISNUMBER(MATCH(G21,Table1[Excluded Spacecraft ID],0)))) -> TRUE | BE21: =BD21*AK21*_xlfn.XLOOKUP(I21,Table2[Date From],Table2[Cession],"Error",-1)*_xlfn.XLOOKUP(I21,'S3123 Consortium Share'!$A$3:$A$5,'S3123 Consortium Share'!$F$3:$F$5,,-1) -> 8543.6594 | BF21: =+BB21-BC21 -> 82019.131 | BG21: {=IF(V21="FIBL",0,INDEX('IGR QS'!$A$1:$D$570,MATCH('Input Data'!V21&'Input Data'!W21&'Input Data'!AM21,'IGR QS'!A:A&'IGR QS'!B:B&'IGR QS'!C:C,0),4))} -> 0.5 | BH21: =+BF21*BG21 -> 41009.565 | BI21: =+BF21-BH21 -> 41009.565 | BJ21: =IF(AND(V21=FIID,(BI21>FIID_Deductible)),MIN(BI21-FIID_Deductible,FIID_Limit),IF(AND(V21=FUL,(BI21>FUL_Deductible)),MIN(BI21-FUL_Deductible,FUL_Limit),0)) -> 0 | BK21: =BH21+BJ21 -> 41009.565 | BL21: =+BI21-BJ21 -> 41009.565 | BN21: =SUMIFS($BL:$BL,$N:$N,$N21,$Q:$Q,1) -> 17510967 | BO21: =SUMIFS($BL:$BL,$N:$N,$N21,$Q:$Q,1,$AL:$AL,$BO$18) -> 14332947 | BP21: =SUMIFS($BL:$BL,$N:$N,$N21,$V:$V,BP$18) -> 3178019.9 | BQ21: =SUMIFS($BK:$BK,$N:$N,$N21) -> 32341726 | BR21: =SUMIFS($AY:$AY,$N:$N,$N21) -> 12463173 | BT21: =SUMIFS($BF:$BF,$C:$C,$C21) -> 7958953.7 | BU21: =SUMIFS($BL:$BL,$C:$C,$C21) -> 2365642.5 | BV21: =SUMIFS($BK:$BK,$C:$C,$C21) -> 5593311.1 | BW21: =SUMIFS($AY:$AY,$C:$C,$C21) -> 1989738.4 | BY21: =IF($K21="GEO-GSO",$AK21*Proton_Flare_InsLoss,0)*Q21 -> 5126.1957 | BZ21: =IF(AND($K21="GEO-GSO",AL21="FUL"),$AK21*Proton_Flare_InsLoss,0)*$Q21 -> 5126.1957 | CA21: =IF(AND($K21="GEO-GSO",AL21="FIID"),$AK21*Proton_Flare_InsLoss,0)*$Q21 -> 0 | CB21: =IF(AND($K21="GEO-GSO",AL21="FIBL"),$AK21*Proton_Flare_InsLoss,0)*$Q21 -> 0 | CC21: =IF($K21="GEO-GSO",(AK21*BG21-BJ21)*Proton_Flare_InsLoss,0)*Q21 -> 2563.0978 | CD21: =IF($K21="GEO-GSO",$AK21*Proton_Flare_InsLoss,0)*$Q21*$R21*0.2 -> 0 | CH21: Airbus Defence and Space (Toulouse) | CI21: =SUMIFS($AK:$AK,$K:$K,"GEO-GSO",$N:$N,$CH21,$Q:$Q,1) -> 2.4905578e+08 | CJ21: =SUMIFS($AK:$AK,$K:$K,"GEO-GSO",$N:$N,$CH21,$Q:$Q,1,$AL:$AL,CJ$19) -> 1.2260773e+08 | CK21: =SUMIFS($AK:$AK,$K:$K,"GEO-GSO",$N:$N,$CH21,$Q:$Q,1,$AL:$AL,CK$19) -> 1.2644805e+08 | CL21: =SUMIFS($AK:$AK,$K:$K,"GEO-GSO",$N:$N,$CH21,$Q:$Q,1,$AL:$AL,"FIBL") -> 0 | CM21: =SUMIFS($BK:$BK,$K:$K,"GEO-GSO",$N:$N,CH21,$Q:$Q,1) -> 1.3502776e+08 | CN21: =SUMIFS($AK:$AK,$K:$K,"GEO-GSO",$N:$N,$CH21,$Q:$Q,1,$R:$R,1)*0.2 -> 0 | CR21: =IF(OR($K21="GEO-GSO",$K21="MEO"),$AK21*Generic_Defect_Loss,0)*$Q21*$P21 -> 10252.391 | CS21: =IF(AND(OR($K21="GEO-GSO",$K21="MEO"),$AL21=CS$19),$AK21*Generic_Defect_Loss,0)*$Q21*$P21 -> 10252.391 | CT21: =IF(AND(OR($K21="GEO-GSO",$K21="MEO"),$AL21=CT$19),$AK21*Generic_Defect_Loss,0)*$Q21*$P21 -> 0 | CU21: =IF(AND(OR($K21="GEO-GSO",$K21="MEO"),$AL21="FIBL"),$AK21*Generic_Defect_Loss,0)*$Q21*$P21 -> 0 | CV21: =IF(OR($K21="GEO-GSO",$K21="MEO"),($AK21*BG21-BJ21)*Generic_Defect_Loss,0)*$Q21*$P21 -> 5126.1957 | CW21: =IF(OR($K21="GEO-GSO",$K21="MEO"),$AK21*Generic_Defect_Loss,0)*$Q21*$P21*$R21*0.2 -> 0 | CY21: =IF(OR($K21="GEO-GSO",$K21="MEO"),$AK21*Space_Debris_Loss,0)*$Q21*$AE21 -> 5126.1957 | CZ21: =IF(AND(OR($K21="GEO-GSO",$K21="MEO"),$AL21=CZ$19),$AK21*Space_Debris_Loss,0)*$Q21*$AE21 -> 5126.1957 | DA21: =IF(AND(OR($K21="GEO-GSO",$K21="MEO",$K21="LEO"),$AL21=DA$19),$AK21*Space_Debris_Loss,0)*$Q21*$AE21 -> 0 | DB21: =IF(AND(OR($K21="GEO-GSO",$K21="MEO"),$AL21="FIBL"),$AK21*Space_Debris_Loss,0)*$Q21*$AE21 -> 0 | DC21: =IF(OR($K21="GEO-GSO",$K21="MEO"),($AK21*BG21-BJ21)*Space_Debris_Loss,0)*$Q21*$AE21 -> 2563.0978 | DD21: =IF(OR($K21="GEO-GSO",$K21="MEO"),$AK21*1,0)*$Q21*$AE21*$R21*0.2 -> 0
A22: =B22&"_"&C22 -> 344664_3 | B22: 344664 | C22: 3 | D22: =IFERROR(MATCH(C22,'[4]Custom Earning Pattern Not Popu'!$B$5:$B$428,0),"NA") -> NA | E22: Orbit | F22: 12 | G22: 8250 | H22: 41223 | I22: 45839 | J22: 46203 | K22: GEO-GSO | L22: 45839 | M22: 46203 | N22: Astrium Satellites SAS (Toulouse) (Part of EADS) | O22: Astrium Satellites SAS (Toulouse) (Part of EADS) | P22: =IFERROR(INDEX($P$10:$P$14,MATCH(DATEDIF($AC$15,M22,"M"),$O$10:$O$14,1)),0) -> 0.2 | Q22: 1 | R22: 0 | S22: =E22 -> Orbit | T22: NULL | U22: Arabsat | V22: FUL | W22: ASO | X22: Arabsat 5B | Y22: EUROSTAR E3000 | Z22: NULL | AA22: 5146207.5 | AC22: =IF(IF(K22="LEO",ROUNDUP(((M22-$AC$15)/30.5),0)*Q22,0)<0,0,IF(K22="LEO",ROUNDUP(((M22-$AC$15)/30.5),0)*Q22,0)) -> 0 | AD22: {=IF(AC22=0,0,INDEX(Summary!$S$4:$S$7,MATCH(AC22,Summary!$R$4:$R$7)+1))} -> 0 | AE22: =IFERROR(INDEX(Summary!$Y$4:$Y$6,MATCH('Input Data'!K22,Summary!$U$4:$U$6,0)),0) -> 0.05 | AF22: =IF(I22>=DATE(2024,7,1),TRUE,FALSE) -> TRUE | AG22: =IF(AF22,INDEX('IG Equity Share'!$B:$B,MATCH(YEAR(I22),'IG Equity Share'!$A:$A,0)),0) -> 0.075 | AH22: =AJ22*AG22*_xlfn.XLOOKUP(I22,'S3123 Consortium Share'!$A$3:$A$5,'S3123 Consortium Share'!$F$3:$F$5,,-1) -> 160818.98 | AI22: 1 | AJ22: =AA22 -> 5146207.5 | AK22: =AJ22/AI22*Q22 -> 5146207.5 | AL22: =V22 -> FUL | AM22: =YEAR(I22) -> 2025 | AO22: =+IF(AND($I22<=AO$8,$I22>=AO$7),$AK22*AO$11,0) -> 0 | AP22: =+IF(AND($I22<=AP$8,$I22>=AP$7),$AK22*AP$11,0) -> 0 | AQ22: =+IF(AND($I22<=AQ$8,$I22>=AQ$7),$AK22*AQ$11,0) -> 0 | AR22: =+IF(AND($I22<=AR$8,$I22>=AR$7),$AK22*AR$11,0) -> 0 | AS22: =+IF(AND($I22<=AS$8,$I22>=AS$7),$AK22*AS$11,0) -> 0 | AT22: =+IF(AND($I22<=AT$8,$I22>=AT$7),$AK22*AT$11,0) -> 0 | AU22: =+IF(AND($I22<=AU$8,$I22>=AU$7),$AK22*AU$11,0) -> 1029241.5 | AV22: =+IF(AND($I22<=AV$8,$I22>=AV$7),$AK22*AV$11,0) -> 0 | AY22: =SUM(AO22:AX22) -> 1029241.5 | AZ22: =+AO22+AP22 -> 0 | BB22: =+AK22-AY22 -> 4116966 | BC22: =SUM(AO22) -> 0 | BD22: =AND(AF22,NOT(ISNUMBER(MATCH(G22,Table1[Excluded Spacecraft ID],0)))) -> TRUE | BE22: =BD22*AK22*_xlfn.XLOOKUP(I22,Table2[Date From],Table2[Cession],"Error",-1)*_xlfn.XLOOKUP(I22,'S3123 Consortium Share'!$A$3:$A$5,'S3123 Consortium Share'!$F$3:$F$5,,-1) -> 428850.62 | BF22: =+BB22-BC22 -> 4116966 | BG22: {=IF(V22="FIBL",0,INDEX('IGR QS'!$A$1:$D$570,MATCH('Input Data'!V22&'Input Data'!W22&'Input Data'!AM22,'IGR QS'!A:A&'IGR QS'!B:B&'IGR QS'!C:C,0),4))} -> 0.5 | BH22: =+BF22*BG22 -> 2058483 | BI22: =+BF22-BH22 -> 2058483 | BJ22: =IF(AND(V22=FIID,(BI22>FIID_Deductible)),MIN(BI22-FIID_Deductible,FIID_Limit),IF(AND(V22=FUL,(BI22>FUL_Deductible)),MIN(BI22-FUL_Deductible,FUL_Limit),0)) -> 0 | BK22: =BH22+BJ22 -> 2058483 | BL22: =+BI22-BJ22 -> 2058483 | BN22: =SUMIFS($BL:$BL,$N:$N,$N22,$Q:$Q,1) -> 17510967 | BO22: =SUMIFS($BL:$BL,$N:$N,$N22,$Q:$Q,1,$AL:$AL,$BO$18) -> 14332947 | BP22: =SUMIFS($BL:$BL,$N:$N,$N22,$V:$V,BP$18) -> 3178019.9 | BQ22: =SUMIFS($BK:$BK,$N:$N,$N22) -> 32341726 | BR22: =SUMIFS($AY:$AY,$N:$N,$N22) -> 12463173 | BT22: =SUMIFS($BF:$BF,$C:$C,$C22) -> 14303554 | BU22: =SUMIFS($BL:$BL,$C:$C,$C22) -> 5429275.4 | BV22: =SUMIFS($BK:$BK,$C:$C,$C22) -> 8874279 | BW22: =SUMIFS($AY:$AY,$C:$C,$C22) -> 3575888.6 | BY22: =IF($K22="GEO-GSO",$AK22*Proton_Flare_InsLoss,0)*Q22 -> 257310.37 | BZ22: =IF(AND($K22="GEO-GSO",AL22="FUL"),$AK22*Proton_Flare_InsLoss,0)*$Q22 -> 257310.37 | CA22: =IF(AND($K22="GEO-GSO",AL22="FIID"),$AK22*Proton_Flare_InsLoss,0)*$Q22 -> 0 | CB22: =IF(AND($K22="GEO-GSO",AL22="FIBL"),$AK22*Proton_Flare_InsLoss,0)*$Q22 -> 0 | CC22: =IF($K22="GEO-GSO",(AK22*BG22-BJ22)*Proton_Flare_InsLoss,0)*Q22 -> 128655.19 | CD22: =IF($K22="GEO-GSO",$AK22*Proton_Flare_InsLoss,0)*$Q22*$R22*0.2 -> 0 | CH22: Lockheed Martin Commercial Space Systems | CI22: =SUMIFS($AK:$AK,$K:$K,"GEO-GSO",$N:$N,$CH22,$Q:$Q,1) -> 36786707 | CJ22: =SUMIFS($AK:$AK,$K:$K,"GEO-GSO",$N:$N,$CH22,$Q:$Q,1,$AL:$AL,CJ$19) -> 36786707 | CK22: =SUMIFS($AK:$AK,$K:$K,"GEO-GSO",$N:$N,$CH22,$Q:$Q,1,$AL:$AL,CK$19) -> 0 | CL22: =SUMIFS($AK:$AK,$K:$K,"GEO-GSO",$N:$N,$CH22,$Q:$Q,1,$AL:$AL,"FIBL") -> 0 | CM22: =SUMIFS($BK:$BK,$K:$K,"GEO-GSO",$N:$N,CH22,$Q:$Q,1) -> 14714683 | CN22: =SUMIFS($AK:$AK,$K:$K,"GEO-GSO",$N:$N,$CH22,$Q:$Q,1,$R:$R,1)*0.2 -> 0 | CR22: =IF(OR($K22="GEO-GSO",$K22="MEO"),$AK22*Generic_Defect_Loss,0)*$Q22*$P22 -> 514620.75 | CS22: =IF(AND(OR($K22="GEO-GSO",$K22="MEO"),$AL22=CS$19),$AK22*Generic_Defect_Loss,0)*$Q22*$P22 -> 514620.75 | CT22: =IF(AND(OR($K22="GEO-GSO",$K22="MEO"),$AL22=CT$19),$AK22*Generic_Defect_Loss,0)*$Q22*$P22 -> 0 | CU22: =IF(AND(OR($K22="GEO-GSO",$K22="MEO"),$AL22="FIBL"),$AK22*Generic_Defect_Loss,0)*$Q22*$P22 -> 0 | CV22: =IF(OR($K22="GEO-GSO",$K22="MEO"),($AK22*BG22-BJ22)*Generic_Defect_Loss,0)*$Q22*$P22 -> 257310.37 | CW22: =IF(OR($K22="GEO-GSO",$K22="MEO"),$AK22*Generic_Defect_Loss,0)*$Q22*$P22*$R22*0.2 -> 0 | CY22: =IF(OR($K22="GEO-GSO",$K22="MEO"),$AK22*Space_Debris_Loss,0)*$Q22*$AE22 -> 257310.37 | CZ22: =IF(AND(OR($K22="GEO-GSO",$K22="MEO"),$AL22=CZ$19),$AK22*Space_Debris_Loss,0)*$Q22*$AE22 -> 257310.37 | DA22: =IF(AND(OR($K22="GEO-GSO",$K22="MEO",$K22="LEO"),$AL22=DA$19),$AK22*Space_Debris_Loss,0)*$Q22*$AE22 -> 0 | DB22: =IF(AND(OR($K22="GEO-GSO",$K22="MEO"),$AL22="FIBL"),$AK22*Space_Debris_Loss,0)*$Q22*$AE22 -> 0 | DC22: =IF(OR($K22="GEO-GSO",$K22="MEO"),($AK22*BG22-BJ22)*Space_Debris_Loss,0)*$Q22*$AE22 -> 128655.19 | DD22: =IF(OR($K22="GEO-GSO",$K22="MEO"),$AK22*1,0)*$Q22*$AE22*$R22*0.2 -> 0
A23: =B23&"_"&C23 -> 344664_4 | B23: 344664 | C23: 4 | D23: =IFERROR(MATCH(C23,'[4]Custom Earning Pattern Not Popu'!$B$5:$B$428,0),"NA") -> NA | E23: Orbit | F23: 12 | G23: 8785 | H23: 41246 | I23: 45839 | J23: 46203 | K23: GEO-GSO | L23: 45839 | M23: 46203 | N23: Astrium Satellites SAS (Toulouse) (Part of EADS) | O23: Astrium Satellites SAS (Toulouse) (Part of EADS) | P23: =IFERROR(INDEX($P$10:$P$14,MATCH(DATEDIF($AC$15,M23,"M"),$O$10:$O$14,1)),0) -> 0.2 | Q23: 1 | R23: 0 | S23: =E23 -> Orbit | T23: NULL | U23: Arabsat | V23: FUL | W23: ASO | X23: Arabsat 5C | Y23: EUROSTAR E3000 | Z23: NULL | AA23: 819140.01 | AC23: =IF(IF(K23="LEO",ROUNDUP(((M23-$AC$15)/30.5),0)*Q23,0)<0,0,IF(K23="LEO",ROUNDUP(((M23-$AC$15)/30.5),0)*Q23,0)) -> 0 | AD23: {=IF(AC23=0,0,INDEX(Summary!$S$4:$S$7,MATCH(AC23,Summary!$R$4:$R$7)+1))} -> 0 | AE23: =IFERROR(INDEX(Summary!$Y$4:$Y$6,MATCH('Input Data'!K23,Summary!$U$4:$U$6,0)),0) -> 0.05 | AF23: =IF(I23>=DATE(2024,7,1),TRUE,FALSE) -> TRUE | AG23: =IF(AF23,INDEX('IG Equity Share'!$B:$B,MATCH(YEAR(I23),'IG Equity Share'!$A:$A,0)),0) -> 0.075 | AH23: =AJ23*AG23*_xlfn.XLOOKUP(I23,'S3123 Consortium Share'!$A$3:$A$5,'S3123 Consortium Share'!$F$3:$F$5,,-1) -> 25598.125 | AI23: 1 | AJ23: =AA23 -> 819140.01 | AK23: =AJ23/AI23*Q23 -> 819140.01 | AL23: =V23 -> FUL | AM23: =YEAR(I23) -> 2025 | AO23: =+IF(AND($I23<=AO$8,$I23>=AO$7),$AK23*AO$11,0) -> 0 | AP23: =+IF(AND($I23<=AP$8,$I23>=AP$7),$AK23*AP$11,0) -> 0 | AQ23: =+IF(AND($I23<=AQ$8,$I23>=AQ$7),$AK23*AQ$11,0) -> 0 | AR23: =+IF(AND($I23<=AR$8,$I23>=AR$7),$AK23*AR$11,0) -> 0 | AS23: =+IF(AND($I23<=AS$8,$I23>=AS$7),$AK23*AS$11,0) -> 0 | AT23: =+IF(AND($I23<=AT$8,$I23>=AT$7),$AK23*AT$11,0) -> 0 | AU23: =+IF(AND($I23<=AU$8,$I23>=AU$7),$AK23*AU$11,0) -> 163828 | AV23: =+IF(AND($I23<=AV$8,$I23>=AV$7),$AK23*AV$11,0) -> 0 | AY23: =SUM(AO23:AX23) -> 163828 | AZ23: =+AO23+AP23 -> 0 | BB23: =+AK23-AY23 -> 655312 | BC23: =SUM(AO23) -> 0 | BD23: =AND(AF23,NOT(ISNUMBER(MATCH(G23,Table1[Excluded Spacecraft ID],0)))) -> TRUE | BE23: =BD23*AK23*_xlfn.XLOOKUP(I23,Table2[Date From],Table2[Cession],"Error",-1)*_xlfn.XLOOKUP(I23,'S3123 Consortium Share'!$A$3:$A$5,'S3123 Consortium Share'!$F$3:$F$5,,-1) -> 68261.667 | BF23: =+BB23-BC23 -> 655312 | BG23: {=IF(V23="FIBL",0,INDEX('IGR QS'!$A$1:$D$570,MATCH('Input Data'!V23&'Input Data'!W23&'Input Data'!AM23,'IGR QS'!A:A&'IGR QS'!B:B&'IGR QS'!C:C,0),4))} -> 0.5 | BH23: =+BF23*BG23 -> 327656 | BI23: =+BF23-BH23 -> 327656 | BJ23: =IF(AND(V23=FIID,(BI23>FIID_Deductible)),MIN(BI23-FIID_Deductible,FIID_Limit),IF(AND(V23=FUL,(BI23>FUL_Deductible)),MIN(BI23-FUL_Deductible,FUL_Limit),0)) -> 0 | BK23: =BH23+BJ23 -> 327656 | BL23: =+BI23-BJ23 -> 327656 | BN23: =SUMIFS($BL:$BL,$N:$N,$N23,$Q:$Q,1) -> 17510967 | BO23: =SUMIFS($BL:$BL,$N:$N,$N23,$Q:$Q,1,$AL:$AL,$BO$18) -> 14332947 | BP23: =SUMIFS($BL:$BL,$N:$N,$N23,$V:$V,BP$18) -> 3178019.9 | BQ23: =SUMIFS($BK:$BK,$N:$N,$N23) -> 32341726 | BR23: =SUMIFS($AY:$AY,$N:$N,$N23) -> 12463173 | BT23: =SUMIFS($BF:$BF,$C:$C,$C23) -> 15269337 | BU23: =SUMIFS($BL:$BL,$C:$C,$C23) -> 3749450.5 | BV23: =SUMIFS($BK:$BK,$C:$C,$C23) -> 11519887 | BW23: =SUMIFS($AY:$AY,$C:$C,$C23) -> 3817334.3 | BY23: =IF($K23="GEO-GSO",$AK23*Proton_Flare_InsLoss,0)*Q23 -> 40957 | BZ23: =IF(AND($K23="GEO-GSO",AL23="FUL"),$AK23*Proton_Flare_InsLoss,0)*$Q23 -> 40957 | CA23: =IF(AND($K23="GEO-GSO",AL23="FIID"),$AK23*Proton_Flare_InsLoss,0)*$Q23 -> 0 | CB23: =IF(AND($K23="GEO-GSO",AL23="FIBL"),$AK23*Proton_Flare_InsLoss,0)*$Q23 -> 0 | CC23: =IF($K23="GEO-GSO",(AK23*BG23-BJ23)*Proton_Flare_InsLoss,0)*Q23 -> 20478.5 | CD23: =IF($K23="GEO-GSO",$AK23*Proton_Flare_InsLoss,0)*$Q23*$R23*0.2 -> 0 | CH23: Airbus Defence and Space | CI23: =SUMIFS($AK:$AK,$K:$K,"GEO-GSO",$N:$N,$CH23,$Q:$Q,1) -> 19814782 | CJ23: =SUMIFS($AK:$AK,$K:$K,"GEO-GSO",$N:$N,$CH23,$Q:$Q,1,$AL:$AL,CJ$19) -> 0 | CK23: =SUMIFS($AK:$AK,$K:$K,"GEO-GSO",$N:$N,$CH23,$Q:$Q,1,$AL:$AL,CK$19) -> 19814782 | CL23: =SUMIFS($AK:$AK,$K:$K,"GEO-GSO",$N:$N,$CH23,$Q:$Q,1,$AL:$AL,"FIBL") -> 0 | CM23: =SUMIFS($BK:$BK,$K:$K,"GEO-GSO",$N:$N,CH23,$Q:$Q,1) -> 13474052 | CN23: =SUMIFS($AK:$AK,$K:$K,"GEO-GSO",$N:$N,$CH23,$Q:$Q,1,$R:$R,1)*0.2 -> 0 | CR23: =IF(OR($K23="GEO-GSO",$K23="MEO"),$AK23*Generic_Defect_Loss,0)*$Q23*$P23 -> 81914.001 | CS23: =IF(AND(OR($K23="GEO-GSO",$K23="MEO"),$AL23=CS$19),$AK23*Generic_Defect_Loss,0)*$Q23*$P23 -> 81914.001 | CT23: =IF(AND(OR($K23="GEO-GSO",$K23="MEO"),$AL23=CT$19),$AK23*Generic_Defect_Loss,0)*$Q23*$P23 -> 0 | CU23: =IF(AND(OR($K23="GEO-GSO",$K23="MEO"),$AL23="FIBL"),$AK23*Generic_Defect_Loss,0)*$Q23*$P23 -> 0 | CV23: =IF(OR($K23="GEO-GSO",$K23="MEO"),($AK23*BG23-BJ23)*Generic_Defect_Loss,0)*$Q23*$P23 -> 40957 | CW23: =IF(OR($K23="GEO-GSO",$K23="MEO"),$AK23*Generic_Defect_Loss,0)*$Q23*$P23*$R23*0.2 -> 0 | CY23: =IF(OR($K23="GEO-GSO",$K23="MEO"),$AK23*Space_Debris_Loss,0)*$Q23*$AE23 -> 40957 | CZ23: =IF(AND(OR($K23="GEO-GSO",$K23="MEO"),$AL23=CZ$19),$AK23*Space_Debris_Loss,0)*$Q23*$AE23 -> 40957 | DA23: =IF(AND(OR($K23="GEO-GSO",$K23="MEO",$K23="LEO"),$AL23=DA$19),$AK23*Space_Debris_Loss,0)*$Q23*$AE23 -> 0 | DB23: =IF(AND(OR($K23="GEO-GSO",$K23="MEO"),$AL23="FIBL"),$AK23*Space_Debris_Loss,0)*$Q23*$AE23 -> 0 | DC23: =IF(OR($K23="GEO-GSO",$K23="MEO"),($AK23*BG23-BJ23)*Space_Debris_Loss,0)*$Q23*$AE23 -> 20478.5 | DD23: =IF(OR($K23="GEO-GSO",$K23="MEO"),$AK23*1,0)*$Q23*$AE23*$R23*0.2 -> 0
A24: =B24&"_"&C24 -> 344664_5 | B24: 344664 | C24: 5 | D24: =IFERROR(MATCH(C24,'[4]Custom Earning Pattern Not Popu'!$B$5:$B$428,0),"NA") -> NA | E24: Orbit | F24: 12 | G24: 8786 | H24: 41408 | I24: 45839 | J24: 46203 | K24: GEO-GSO | L24: 45839 | M24: 46203 | N24: Airbus Defence and Space (Toulouse) | O24: Airbus Defence and Space (Toulouse) | P24: =IFERROR(INDEX($P$10:$P$14,MATCH(DATEDIF($AC$15,M24,"M"),$O$10:$O$14,1)),0) -> 0.2 | Q24: 1 | R24: 0 | S24: =E24 -> Orbit | T24: NULL | U24: Arabsat | V24: FUL | W24: ASO | X24: Arabsat BADR 7 | Y24: EUROSTAR E3000 | Z24: NULL | AA24: 9517167.3 | AC24: =IF(IF(K24="LEO",ROUNDUP(((M24-$AC$15)/30.5),0)*Q24,0)<0,0,IF(K24="LEO",ROUNDUP(((M24-$AC$15)/30.5),0)*Q24,0)) -> 0 | AD24: {=IF(AC24=0,0,INDEX(Summary!$S$4:$S$7,MATCH(AC24,Summary!$R$4:$R$7)+1))} -> 0 | AE24: =IFERROR(INDEX(Summary!$Y$4:$Y$6,MATCH('Input Data'!K24,Summary!$U$4:$U$6,0)),0) -> 0.05 | AF24: =IF(I24>=DATE(2024,7,1),TRUE,FALSE) -> TRUE | AG24: =IF(AF24,INDEX('IG Equity Share'!$B:$B,MATCH(YEAR(I24),'IG Equity Share'!$A:$A,0)),0) -> 0.075 | AH24: =AJ24*AG24*_xlfn.XLOOKUP(I24,'S3123 Consortium Share'!$A$3:$A$5,'S3123 Consortium Share'!$F$3:$F$5,,-1) -> 297411.48 | AI24: 1 | AJ24: =AA24 -> 9517167.3 | AK24: =AJ24/AI24*Q24 -> 9517167.3 | AL24: =V24 -> FUL | AM24: =YEAR(I24) -> 2025 | AO24: =+IF(AND($I24<=AO$8,$I24>=AO$7),$AK24*AO$11,0) -> 0 | AP24: =+IF(AND($I24<=AP$8,$I24>=AP$7),$AK24*AP$11,0) -> 0 | AQ24: =+IF(AND($I24<=AQ$8,$I24>=AQ$7),$AK24*AQ$11,0) -> 0 | AR24: =+IF(AND($I24<=AR$8,$I24>=AR$7),$AK24*AR$11,0) -> 0 | AS24: =+IF(AND($I24<=AS$8,$I24>=AS$7),$AK24*AS$11,0) -> 0 | AT24: =+IF(AND($I24<=AT$8,$I24>=AT$7),$AK24*AT$11,0) -> 0 | AU24: =+IF(AND($I24<=AU$8,$I24>=AU$7),$AK24*AU$11,0) -> 1903433.5 | AV24: =+IF(AND($I24<=AV$8,$I24>=AV$7),$AK24*AV$11,0) -> 0 | AY24: =SUM(AO24:AX24) -> 1903433.5 | AZ24: =+AO24+AP24 -> 0 | BB24: =+AK24-AY24 -> 7613733.9 | BC24: =SUM(AO24) -> 0 | BD24: =AND(AF24,NOT(ISNUMBER(MATCH(G24,Table1[Excluded Spacecraft ID],0)))) -> TRUE | BE24: =BD24*AK24*_xlfn.XLOOKUP(I24,Table2[Date From],Table2[Cession],"Error",-1)*_xlfn.XLOOKUP(I24,'S3123 Consortium Share'!$A$3:$A$5,'S3123 Consortium Share'!$F$3:$F$5,,-1) -> 793097.28 | BF24: =+BB24-BC24 -> 7613733.9 | BG24: {=IF(V24="FIBL",0,INDEX('IGR QS'!$A$1:$D$570,MATCH('Input Data'!V24&'Input Data'!W24&'Input Data'!AM24,'IGR QS'!A:A&'IGR QS'!B:B&'IGR QS'!C:C,0),4))} -> 0.5 | BH24: =+BF24*BG24 -> 3806866.9 | BI24: =+BF24-BH24 -> 3806866.9 | BJ24: =IF(AND(V24=FIID,(BI24>FIID_Deductible)),MIN(BI24-FIID_Deductible,FIID_Limit),IF(AND(V24=FUL,(BI24>FUL_Deductible)),MIN(BI24-FUL_Deductible,FUL_Limit),0)) -> 0 | BK24: =BH24+BJ24 -> 3806866.9 | BL24: =+BI24-BJ24 -> 3806866.9 | BN24: =SUMIFS($BL:$BL,$N:$N,$N24,$Q:$Q,1) -> 66471396 | BO24: =SUMIFS($BL:$BL,$N:$N,$N24,$Q:$Q,1,$AL:$AL,$BO$18) -> 49043092 | BP24: =SUMIFS($BL:$BL,$N:$N,$N24,$V:$V,BP$18) -> 17428305 | BQ24: =SUMIFS($BK:$BK,$N:$N,$N24) -> 1.4780349e+08 | BR24: =SUMIFS($AY:$AY,$N:$N,$N24) -> 53568720 | BT24: =SUMIFS($BF:$BF,$C:$C,$C24) -> 24656652 | BU24: =SUMIFS($BL:$BL,$C:$C,$C24) -> 8989906.7 | BV24: =SUMIFS($BK:$BK,$C:$C,$C24) -> 15666745 | BW24: =SUMIFS($AY:$AY,$C:$C,$C24) -> 6164163 | BY24: =IF($K24="GEO-GSO",$AK24*Proton_Flare_InsLoss,0)*Q24 -> 475858.37 | BZ24: =IF(AND($K24="GEO-GSO",AL24="FUL"),$AK24*Proton_Flare_InsLoss,0)*$Q24 -> 475858.37 | CA24: =IF(AND($K24="GEO-GSO",AL24="FIID"),$AK24*Proton_Flare_InsLoss,0)*$Q24 -> 0 | CB24: =IF(AND($K24="GEO-GSO",AL24="FIBL"),$AK24*Proton_Flare_InsLoss,0)*$Q24 -> 0 | CC24: =IF($K24="GEO-GSO",(AK24*BG24-BJ24)*Proton_Flare_InsLoss,0)*Q24 -> 237929.18 | CD24: =IF($K24="GEO-GSO",$AK24*Proton_Flare_InsLoss,0)*$Q24*$R24*0.2 -> 0 | CH24: Alcatel Alenia Space (Cannes) | CI24: =SUMIFS($AK:$AK,$K:$K,"GEO-GSO",$N:$N,$CH24,$Q:$Q,1) -> 3567555.6 | CJ24: =SUMIFS($AK:$AK,$K:$K,"GEO-GSO",$N:$N,$CH24,$Q:$Q,1,$AL:$AL,CJ$19) -> 0 | CK24: =SUMIFS($AK:$AK,$K:$K,"GEO-GSO",$N:$N,$CH24,$Q:$Q,1,$AL:$AL,CK$19) -> 3567555.6 | CL24: =SUMIFS($AK:$AK,$K:$K,"GEO-GSO",$N:$N,$CH24,$Q:$Q,1,$AL:$AL,"FIBL") -> 0 | CM24: =SUMIFS($BK:$BK,$K:$K,"GEO-GSO",$N:$N,CH24,$Q:$Q,1) -> 2425937.8 | CN24: =SUMIFS($AK:$AK,$K:$K,"GEO-GSO",$N:$N,$CH24,$Q:$Q,1,$R:$R,1)*0.2 -> 0 | CR24: =IF(OR($K24="GEO-GSO",$K24="MEO"),$AK24*Generic_Defect_Loss,0)*$Q24*$P24 -> 951716.73 | CS24: =IF(AND(OR($K24="GEO-GSO",$K24="MEO"),$AL24=CS$19),$AK24*Generic_Defect_Loss,0)*$Q24*$P24 -> 951716.73 | CT24: =IF(AND(OR($K24="GEO-GSO",$K24="MEO"),$AL24=CT$19),$AK24*Generic_Defect_Loss,0)*$Q24*$P24 -> 0 | CU24: =IF(AND(OR($K24="GEO-GSO",$K24="MEO"),$AL24="FIBL"),$AK24*Generic_Defect_Loss,0)*$Q24*$P24 -> 0 | CV24: =IF(OR($K24="GEO-GSO",$K24="MEO"),($AK24*BG24-BJ24)*Generic_Defect_Loss,0)*$Q24*$P24 -> 475858.37 | CW24: =IF(OR($K24="GEO-GSO",$K24="MEO"),$AK24*Generic_Defect_Loss,0)*$Q24*$P24*$R24*0.2 -> 0 | CY24: =IF(OR($K24="GEO-GSO",$K24="MEO"),$AK24*Space_Debris_Loss,0)*$Q24*$AE24 -> 475858.37 | CZ24: =IF(AND(OR($K24="GEO-GSO",$K24="MEO"),$AL24=CZ$19),$AK24*Space_Debris_Loss,0)*$Q24*$AE24 -> 475858.37 | DA24: =IF(AND(OR($K24="GEO-GSO",$K24="MEO",$K24="LEO"),$AL24=DA$19),$AK24*Space_Debris_Loss,0)*$Q24*$AE24 -> 0 | DB24: =IF(AND(OR($K24="GEO-GSO",$K24="MEO"),$AL24="FIBL"),$AK24*Space_Debris_Loss,0)*$Q24*$AE24 -> 0 | DC24: =IF(OR($K24="GEO-GSO",$K24="MEO"),($AK24*BG24-BJ24)*Space_Debris_Loss,0)*$Q24*$AE24 -> 237929.18 | DD24: =IF(OR($K24="GEO-GSO",$K24="MEO"),$AK24*1,0)*$Q24*$AE24*$R24*0.2 -> 0
A25: =B25&"_"&C25 -> 344664_6 | B25: 344664 | C25: 6 | D25: =IFERROR(MATCH(C25,'[4]Custom Earning Pattern Not Popu'!$B$5:$B$428,0),"NA") -> NA | E25: Orbit | F25: 12 | G25: 9559 | H25: 41785 | I25: 45839 | J25: 46203 | K25: GEO-GSO | L25: 45839 | M25: 46203 | N25: Lockheed Martin Commercial Space Systems | O25: Lockheed Martin Commercial Space Systems | P25: =IFERROR(INDEX($P$10:$P$14,MATCH(DATEDIF($AC$15,M25,"M"),$O$10:$O$14,1)),0) -> 0.2 | Q25: 1 | R25: 0 | S25: =E25 -> Orbit | T25: NULL | U25: Arabsat | V25: FUL | W25: ASO | X25: Arabsat 6A | Y25: LM 2100 | Z25: NULL | AA25: 14528090 | AC25: =IF(IF(K25="LEO",ROUNDUP(((M25-$AC$15)/30.5),0)*Q25,0)<0,0,IF(K25="LEO",ROUNDUP(((M25-$AC$15)/30.5),0)*Q25,0)) -> 0 | AD25: {=IF(AC25=0,0,INDEX(Summary!$S$4:$S$7,MATCH(AC25,Summary!$R$4:$R$7)+1))} -> 0 | AE25: =IFERROR(INDEX(Summary!$Y$4:$Y$6,MATCH('Input Data'!K25,Summary!$U$4:$U$6,0)),0) -> 0.05 | AF25: =IF(I25>=DATE(2024,7,1),TRUE,FALSE) -> TRUE | AG25: =IF(AF25,INDEX('IG Equity Share'!$B:$B,MATCH(YEAR(I25),'IG Equity Share'!$A:$A,0)),0) -> 0.075 | AH25: =AJ25*AG25*_xlfn.XLOOKUP(I25,'S3123 Consortium Share'!$A$3:$A$5,'S3123 Consortium Share'!$F$3:$F$5,,-1) -> 454002.81 | AI25: 1 | AJ25: =AA25 -> 14528090 | AK25: =AJ25/AI25*Q25 -> 14528090 | AL25: =V25 -> FUL | AM25: =YEAR(I25) -> 2025 | AN25: =INDEX('[2]Input Data'!$AH:$AH,MATCH(A25,'[2]Input Data'!$A:$A,0),1)-AH25 -> 0 | AO25: =+IF(AND($I25<=AO$8,$I25>=AO$7),$AK25*AO$11,0) -> 0 | AP25: =+IF(AND($I25<=AP$8,$I25>=AP$7),$AK25*AP$11,0) -> 0 | AQ25: =+IF(AND($I25<=AQ$8,$I25>=AQ$7),$AK25*AQ$11,0) -> 0 | AR25: =+IF(AND($I25<=AR$8,$I25>=AR$7),$AK25*AR$11,0) -> 0 | AS25: =+IF(AND($I25<=AS$8,$I25>=AS$7),$AK25*AS$11,0) -> 0 | AT25: =+IF(AND($I25<=AT$8,$I25>=AT$7),$AK25*AT$11,0) -> 0 | AU25: =+IF(AND($I25<=AU$8,$I25>=AU$7),$AK25*AU$11,0) -> 2905618 | AV25: =+IF(AND($I25<=AV$8,$I25>=AV$7),$AK25*AV$11,0) -> 0 | AY25: =SUM(AO25:AX25) -> 2905618 | AZ25: =+AO25+AP25 -> 0 | BB25: =+AK25-AY25 -> 11622472 | BC25: =SUM(AO25) -> 0 | BD25: =AND(AF25,NOT(ISNUMBER(MATCH(G25,Table1[Excluded Spacecraft ID],0)))) -> TRUE | BE25: =BD25*AK25*_xlfn.XLOOKUP(I25,Table2[Date From],Table2[Cession],"Error",-1)*_xlfn.XLOOKUP(I25,'S3123 Consortium Share'!$A$3:$A$5,'S3123 Consortium Share'!$F$3:$F$5,,-1) -> 1210674.2 | BF25: =+BB25-BC25 -> 11622472 | BG25: {=IF(V25="FIBL",0,INDEX('IGR QS'!$A$1:$D$570,MATCH('Input Data'!V25&'Input Data'!W25&'Input Data'!AM25,'IGR QS'!A:A&'IGR QS'!B:B&'IGR QS'!C:C,0),4))} -> 0.5 | BH25: =+BF25*BG25 -> 5811236 | BI25: =+BF25-BH25 -> 5811236 | BJ25: =IF(AND(V25=FIID,(BI25>FIID_Deductible)),MIN(BI25-FIID_Deductible,FIID_Limit),IF(AND(V25=FUL,(BI25>FUL_Deductible)),MIN(BI25-FUL_Deductible,FUL_Limit),0)) -> 0 | BK25: =BH25+BJ25 -> 5811236 | BL25: =+BI25-BJ25 -> 5811236 | BN25: =SUMIFS($BL:$BL,$N:$N,$N25,$Q:$Q,1) -> 14714683 | BO25: =SUMIFS($BL:$BL,$N:$N,$N25,$Q:$Q,1,$AL:$AL,$BO$18) -> 14714683 | BP25: =SUMIFS($BL:$BL,$N:$N,$N25,$V:$V,BP$18) -> 0 | BQ25: =SUMIFS($BK:$BK,$N:$N,$N25) -> 14714683 | BR25: =SUMIFS($AY:$AY,$N:$N,$N25) -> 7357341.4 | BT25: =SUMIFS($BF:$BF,$C:$C,$C25) -> 16735239 | BU25: =SUMIFS($BL:$BL,$C:$C,$C25) -> 6578151 | BV25: =SUMIFS($BK:$BK,$C:$C,$C25) -> 10157088 | BW25: =SUMIFS($AY:$AY,$C:$C,$C25) -> 4183809.8 | BY25: =IF($K25="GEO-GSO",$AK25*Proton_Flare_InsLoss,0)*Q25 -> 726404.49 | BZ25: =IF(AND($K25="GEO-GSO",AL25="FUL"),$AK25*Proton_Flare_InsLoss,0)*$Q25 -> 726404.49 | CA25: =IF(AND($K25="GEO-GSO",AL25="FIID"),$AK25*Proton_Flare_InsLoss,0)*$Q25 -> 0 | CB25: =IF(AND($K25="GEO-GSO",AL25="FIBL"),$AK25*Proton_Flare_InsLoss,0)*$Q25 -> 0 | CC25: =IF($K25="GEO-GSO",(AK25*BG25-BJ25)*Proton_Flare_InsLoss,0)*Q25 -> 363202.25 | CD25: =IF($K25="GEO-GSO",$AK25*Proton_Flare_InsLoss,0)*$Q25*$R25*0.2 -> 0 | CH25: Boeing Satellite Systems Inc. | CI25: =SUMIFS($AK:$AK,$K:$K,"GEO-GSO",$N:$N,$CH25,$Q:$Q,1) -> 1.1271144e+08 | CJ25: =SUMIFS($AK:$AK,$K:$K,"GEO-GSO",$N:$N,$CH25,$Q:$Q,1,$AL:$AL,CJ$19) -> 1.0436747e+08 | CK25: =SUMIFS($AK:$AK,$K:$K,"GEO-GSO",$N:$N,$CH25,$Q:$Q,1,$AL:$AL,CK$19) -> 8343968.2 | CL25: =SUMIFS($AK:$AK,$K:$K,"GEO-GSO",$N:$N,$CH25,$Q:$Q,1,$AL:$AL,"FIBL") -> 0 | CM25: =SUMIFS($BK:$BK,$K:$K,"GEO-GSO",$N:$N,CH25,$Q:$Q,1) -> 44620885 | CN25: =SUMIFS($AK:$AK,$K:$K,"GEO-GSO",$N:$N,$CH25,$Q:$Q,1,$R:$R,1)*0.2 -> 0 | CR25: =IF(OR($K25="GEO-GSO",$K25="MEO"),$AK25*Generic_Defect_Loss,0)*$Q25*$P25 -> 1452809 | CS25: =IF(AND(OR($K25="GEO-GSO",$K25="MEO"),$AL25=CS$19),$AK25*Generic_Defect_Loss,0)*$Q25*$P25 -> 1452809 | CT25: =IF(AND(OR($K25="GEO-GSO",$K25="MEO"),$AL25=CT$19),$AK25*Generic_Defect_Loss,0)*$Q25*$P25 -> 0 | CU25: =IF(AND(OR($K25="GEO-GSO",$K25="MEO"),$AL25="FIBL"),$AK25*Generic_Defect_Loss,0)*$Q25*$P25 -> 0 | CV25: =IF(OR($K25="GEO-GSO",$K25="MEO"),($AK25*BG25-BJ25)*Generic_Defect_Loss,0)*$Q25*$P25 -> 726404.49 | CW25: =IF(OR($K25="GEO-GSO",$K25="MEO"),$AK25*Generic_Defect_Loss,0)*$Q25*$P25*$R25*0.2 -> 0 | CY25: =IF(OR($K25="GEO-GSO",$K25="MEO"),$AK25*Space_Debris_Loss,0)*$Q25*$AE25 -> 726404.49 | CZ25: =IF(AND(OR($K25="GEO-GSO",$K25="MEO"),$AL25=CZ$19),$AK25*Space_Debris_Loss,0)*$Q25*$AE25 -> 726404.49 | DA25: =IF(AND(OR($K25="GEO-GSO",$K25="MEO",$K25="LEO"),$AL25=DA$19),$AK25*Space_Debris_Loss,0)*$Q25*$AE25 -> 0 | DB25: =IF(AND(OR($K25="GEO-GSO",$K25="MEO"),$AL25="FIBL"),$AK25*Space_Debris_Loss,0)*$Q25*$AE25 -> 0 | DC25: =IF(OR($K25="GEO-GSO",$K25="MEO"),($AK25*BG25-BJ25)*Space_Debris_Loss,0)*$Q25*$AE25 -> 363202.25 | DD25: =IF(OR($K25="GEO-GSO",$K25="MEO"),$AK25*1,0)*$Q25*$AE25*$R25*0.2 -> 0
A26: =B26&"_"&C26 -> 344558_1 | B26: 344558 | C26: 1 | D26: =IFERROR(MATCH(C26,'[4]Custom Earning Pattern Not Popu'!$B$5:$B$428,0),"NA") -> NA | E26: Orbit | F26: 12 | G26: 16310 | H26: 44407 | I26: 45839 | J26: 46203 | K26: GEO-GSO | L26: 45839 | M26: 46203 | N26: Airbus Defence and Space | O26: Airbus Defence and Space | P26: =IFERROR(INDEX($P$10:$P$14,MATCH(DATEDIF($AC$15,M26,"M"),$O$10:$O$14,1)),0) -> 0.2 | Q26: 1 | R26: 0 | S26: =E26 -> Orbit | T26: NULL | U26: Eutelsat | V26: FIID | W26: ASO | X26: EUTELSAT 36D | Y26: EUROSTAR NEO | Z26: NULL | AA26: 19814782 | AC26: =IF(IF(K26="LEO",ROUNDUP(((M26-$AC$15)/30.5),0)*Q26,0)<0,0,IF(K26="LEO",ROUNDUP(((M26-$AC$15)/30.5),0)*Q26,0)) -> 0 | AD26: {=IF(AC26=0,0,INDEX(Summary!$S$4:$S$7,MATCH(AC26,Summary!$R$4:$R$7)+1))} -> 0 | AE26: =IFERROR(INDEX(Summary!$Y$4:$Y$6,MATCH('Input Data'!K26,Summary!$U$4:$U$6,0)),0) -> 0.05 | AF26: =IF(I26>=DATE(2024,7,1),TRUE,FALSE) -> TRUE | AG26: =IF(AF26,INDEX('IG Equity Share'!$B:$B,MATCH(YEAR(I26),'IG Equity Share'!$A:$A,0)),0) -> 0.075 | AH26: =AJ26*AG26*_xlfn.XLOOKUP(I26,'S3123 Consortium Share'!$A$3:$A$5,'S3123 Consortium Share'!$F$3:$F$5,,-1) -> 619211.95 | AI26: 1 | AJ26: =AA26 -> 19814782 | AK26: =AJ26/AI26*Q26 -> 19814782 | AL26: =V26 -> FIID | AM26: =YEAR(I26) -> 2025 | AN26: =INDEX('[2]Input Data'!$AH:$AH,MATCH(A26,'[2]Input Data'!$A:$A,0),1)-AH26 -> 0 | AO26: =+IF(AND($I26<=AO$8,$I26>=AO$7),$AK26*AO$11,0) -> 0 | AP26: =+IF(AND($I26<=AP$8,$I26>=AP$7),$AK26*AP$11,0) -> 0 | AQ26: =+IF(AND($I26<=AQ$8,$I26>=AQ$7),$AK26*AQ$11,0) -> 0 | AR26: =+IF(AND($I26<=AR$8,$I26>=AR$7),$AK26*AR$11,0) -> 0 | AS26: =+IF(AND($I26<=AS$8,$I26>=AS$7),$AK26*AS$11,0) -> 0 | AT26: =+IF(AND($I26<=AT$8,$I26>=AT$7),$AK26*AT$11,0) -> 0 | AU26: =+IF(AND($I26<=AU$8,$I26>=AU$7),$AK26*AU$11,0) -> 3962956.5 | AV26: =+IF(AND($I26<=AV$8,$I26>=AV$7),$AK26*AV$11,0) -> 0 | AY26: =SUM(AO26:AX26) -> 3962956.5 | AZ26: =+AO26+AP26 -> 0 | BB26: =+AK26-AY26 -> 15851826 | BC26: =SUM(AO26) -> 0 | BD26: =AND(AF26,NOT(ISNUMBER(MATCH(G26,Table1[Excluded Spacecraft ID],0)))) -> TRUE | BE26: =BD26*AK26*_xlfn.XLOOKUP(I26,Table2[Date From],Table2[Cession],"Error",-1)*_xlfn.XLOOKUP(I26,'S3123 Consortium Share'!$A$3:$A$5,'S3123 Consortium Share'!$F$3:$F$5,,-1) -> 1651231.9 | BF26: =+BB26-BC26 -> 15851826 | BG26: {=IF(V26="FIBL",0,INDEX('IGR QS'!$A$1:$D$570,MATCH('Input Data'!V26&'Input Data'!W26&'Input Data'!AM26,'IGR QS'!A:A&'IGR QS'!B:B&'IGR QS'!C:C,0),4))} -> 0.85 | BH26: =+BF26*BG26 -> 13474052 | BI26: =+BF26-BH26 -> 2377773.9 | BJ26: =IF(AND(V26=FIID,(BI26>FIID_Deductible)),MIN(BI26-FIID_Deductible,FIID_Limit),IF(AND(V26=FUL,(BI26>FUL_Deductible)),MIN(BI26-FUL_Deductible,FUL_Limit),0)) -> 0 | BK26: =BH26+BJ26 -> 13474052 | BL26: =+BI26-BJ26 -> 2377773.9 | BN26: =SUMIFS($BL:$BL,$N:$N,$N26,$Q:$Q,1) -> 2377773.9 | BO26: =SUMIFS($BL:$BL,$N:$N,$N26,$Q:$Q,1,$AL:$AL,$BO$18) -> 0 | BP26: =SUMIFS($BL:$BL,$N:$N,$N26,$V:$V,BP$18) -> 2377773.9 | BQ26: =SUMIFS($BK:$BK,$N:$N,$N26) -> 13474052 | BR26: =SUMIFS($AY:$AY,$N:$N,$N26) -> 3962956.5 | BT26: =SUMIFS($BF:$BF,$C:$C,$C26) -> 42889947 | BU26: =SUMIFS($BL:$BL,$C:$C,$C26) -> 15281915 | BV26: =SUMIFS($BK:$BK,$C:$C,$C26) -> 27608031 | BW26: =SUMIFS($AY:$AY,$C:$C,$C26) -> 10722487 | BY26: =IF($K26="GEO-GSO",$AK26*Proton_Flare_InsLoss,0)*Q26 -> 990739.12 | BZ26: =IF(AND($K26="GEO-GSO",AL26="FUL"),$AK26*Proton_Flare_InsLoss,0)*$Q26 -> 0 | CA26: =IF(AND($K26="GEO-GSO",AL26="FIID"),$AK26*Proton_Flare_InsLoss,0)*$Q26 -> 990739.12 | CB26: =IF(AND($K26="GEO-GSO",AL26="FIBL"),$AK26*Proton_Flare_InsLoss,0)*$Q26 -> 0 | CC26: =IF($K26="GEO-GSO",(AK26*BG26-BJ26)*Proton_Flare_InsLoss,0)*Q26 -> 842128.25 | CD26: =IF($K26="GEO-GSO",$AK26*Proton_Flare_InsLoss,0)*$Q26*$R26*0.2 -> 0 | CH26: Thales Alenia Space France (Cannes) | CI26: =SUMIFS($AK:$AK,$K:$K,"GEO-GSO",$N:$N,$CH26,$Q:$Q,1) -> 1.6628586e+08 | CJ26: =SUMIFS($AK:$AK,$K:$K,"GEO-GSO",$N:$N,$CH26,$Q:$Q,1,$AL:$AL,CJ$19) -> 50028573 | CK26: =SUMIFS($AK:$AK,$K:$K,"GEO-GSO",$N:$N,$CH26,$Q:$Q,1,$AL:$AL,CK$19) -> 1.1625728e+08 | CL26: =SUMIFS($AK:$AK,$K:$K,"GEO-GSO",$N:$N,$CH26,$Q:$Q,1,$AL:$AL,"FIBL") -> 0 | CM26: =SUMIFS($BK:$BK,$K:$K,"GEO-GSO",$N:$N,CH26,$Q:$Q,1) -> 99066383 | CN26: =SUMIFS($AK:$AK,$K:$K,"GEO-GSO",$N:$N,$CH26,$Q:$Q,1,$R:$R,1)*0.2 -> 0 | CR26: =IF(OR($K26="GEO-GSO",$K26="MEO"),$AK26*Generic_Defect_Loss,0)*$Q26*$P26 -> 1981478.2 | CS26: =IF(AND(OR($K26="GEO-GSO",$K26="MEO"),$AL26=CS$19),$AK26*Generic_Defect_Loss,0)*$Q26*$P26 -> 0 | CT26: =IF(AND(OR($K26="GEO-GSO",$K26="MEO"),$AL26=CT$19),$AK26*Generic_Defect_Loss,0)*$Q26*$P26 -> 1981478.2 | CU26: =IF(AND(OR($K26="GEO-GSO",$K26="MEO"),$AL26="FIBL"),$AK26*Generic_Defect_Loss,0)*$Q26*$P26 -> 0 | CV26: =IF(OR($K26="GEO-GSO",$K26="MEO"),($AK26*BG26-BJ26)*Generic_Defect_Loss,0)*$Q26*$P26 -> 1684256.5 | CW26: =IF(OR($K26="GEO-GSO",$K26="MEO"),$AK26*Generic_Defect_Loss,0)*$Q26*$P26*$R26*0.2 -> 0 | CY26: =IF(OR($K26="GEO-GSO",$K26="MEO"),$AK26*Space_Debris_Loss,0)*$Q26*$AE26 -> 990739.12 | CZ26: =IF(AND(OR($K26="GEO-GSO",$K26="MEO"),$AL26=CZ$19),$AK26*Space_Debris_Loss,0)*$Q26*$AE26 -> 0 | DA26: =IF(AND(OR($K26="GEO-GSO",$K26="MEO"),$AL26=DA$19),$AK26*Space_Debris_Loss,0)*$Q26*$AE26 -> 990739.12 | DB26: =IF(AND(OR($K26="GEO-GSO",$K26="MEO"),$AL26="FIBL"),$AK26*Space_Debris_Loss,0)*$Q26*$AE26 -> 0 | DC26: =IF(OR($K26="GEO-GSO",$K26="MEO"),($AK26*BG26-BJ26)*Space_Debris_Loss,0)*$Q26*$AE26 -> 842128.25 | DD26: =IF(OR($K26="GEO-GSO",$K26="MEO"),$AK26*1,0)*$Q26*$AE26*$R26*0.2 -> 0
A27: =B27&"_"&C27 -> 344558_2 | B27: 344558 | C27: 2 | D27: =IFERROR(MATCH(C27,'[4]Custom Earning Pattern Not Popu'!$B$5:$B$428,0),"NA") -> NA | E27: Orbit | F27: 12 | G27: 8137 | H27: 43636 | I27: 45839 | J27: 46203 | K27: GEO-GSO | L27: 45839 | M27: 46203 | N27: Alcatel Alenia Space (Cannes) | O27: Alcatel Alenia Space (Cannes) | P27: =IFERROR(INDEX($P$10:$P$14,MATCH(DATEDIF($AC$15,M27,"M"),$O$10:$O$14,1)),0) -> 0.2 | Q27: 1 | R27: 0 | S27: =E27 -> Orbit | T27: NULL | U27: Eutelsat | V27: FIID | W27: ASO | X27: W7/E36B | Y27: SPACEBUS 4000 | Z27: NULL | AA27: 3567555.6 | AC27: =IF(IF(K27="LEO",ROUNDUP(((M27-$AC$15)/30.5),0)*Q27,0)<0,0,IF(K27="LEO",ROUNDUP(((M27-$AC$15)/30.5),0)*Q27,0)) -> 0 | AD27: {=IF(AC27=0,0,INDEX(Summary!$S$4:$S$7,MATCH(AC27,Summary!$R$4:$R$7)+1))} -> 0 | AE27: =IFERROR(INDEX(Summary!$Y$4:$Y$6,MATCH('Input Data'!K27,Summary!$U$4:$U$6,0)),0) -> 0.05 | AF27: =IF(I27>=DATE(2024,7,1),TRUE,FALSE) -> TRUE | AG27: =IF(AF27,INDEX('IG Equity Share'!$B:$B,MATCH(YEAR(I27),'IG Equity Share'!$A:$A,0)),0) -> 0.075 | AH27: =AJ27*AG27*_xlfn.XLOOKUP(I27,'S3123 Consortium Share'!$A$3:$A$5,'S3123 Consortium Share'!$F$3:$F$5,,-1) -> 111486.11 | AI27: 1 | AJ27: =AA27 -> 3567555.6 | AK27: =AJ27/AI27*Q27 -> 3567555.6 | AL27: =V27 -> FIID | AM27: =YEAR(I27) -> 2025 | AO27: =+IF(AND($I27<=AO$8,$I27>=AO$7),$AK27*AO$11,0) -> 0 | AP27: =+IF(AND($I27<=AP$8,$I27>=AP$7),$AK27*AP$11,0) -> 0 | AQ27: =+IF(AND($I27<=AQ$8,$I27>=AQ$7),$AK27*AQ$11,0) -> 0 | AR27: =+IF(AND($I27<=AR$8,$I27>=AR$7),$AK27*AR$11,0) -> 0 | AS27: =+IF(AND($I27<=AS$8,$I27>=AS$7),$AK27*AS$11,0) -> 0 | AT27: =+IF(AND($I27<=AT$8,$I27>=AT$7),$AK27*AT$11,0) -> 0 | AU27: =+IF(AND($I27<=AU$8,$I27>=AU$7),$AK27*AU$11,0) -> 713511.11 | AV27: =+IF(AND($I27<=AV$8,$I27>=AV$7),$AK27*AV$11,0) -> 0 | AY27: =SUM(AO27:AX27) -> 713511.11 | AZ27: =+AO27+AP27 -> 0 | BB27: =+AK27-AY27 -> 2854044.5 | BC27: =SUM(AO27) -> 0 | BD27: =AND(AF27,NOT(ISNUMBER(MATCH(G27,Table1[Excluded Spacecraft ID],0)))) -> TRUE | BE27: =BD27*AK27*_xlfn.XLOOKUP(I27,Table2[Date From],Table2[Cession],"Error",-1)*_xlfn.XLOOKUP(I27,'S3123 Consortium Share'!$A$3:$A$5,'S3123 Consortium Share'!$F$3:$F$5,,-1) -> 297296.3 | BF27: =+BB27-BC27 -> 2854044.5 | BG27: {=IF(V27="FIBL",0,INDEX('IGR QS'!$A$1:$D$570,MATCH('Input Data'!V27&'Input Data'!W27&'Input Data'!AM27,'IGR QS'!A:A&'IGR QS'!B:B&'IGR QS'!C:C,0),4))} -> 0.85 | BH27: =+BF27*BG27 -> 2425937.8 | BI27: =+BF27-BH27 -> 428106.67 | BJ27: =IF(AND(V27=FIID,(BI27>FIID_Deductible)),MIN(BI27-FIID_Deductible,FIID_Limit),IF(AND(V27=FUL,(BI27>FUL_Deductible)),MIN(BI27-FUL_Deductible,FUL_Limit),0)) -> 0 | BK27: =BH27+BJ27 -> 2425937.8 | BL27: =+BI27-BJ27 -> 428106.67 | BN27: =SUMIFS($BL:$BL,$N:$N,$N27,$Q:$Q,1) -> 428106.67 | BO27: =SUMIFS($BL:$BL,$N:$N,$N27,$Q:$Q,1,$AL:$AL,$BO$18) -> 0 | BP27: =SUMIFS($BL:$BL,$N:$N,$N27,$V:$V,BP$18) -> 428106.67 | BQ27: =SUMIFS($BK:$BK,$N:$N,$N27) -> 2425937.8 | BR27: =SUMIFS($AY:$AY,$N:$N,$N27) -> 713511.11 | BT27: =SUMIFS($BF:$BF,$C:$C,$C27) -> 7958953.7 | BU27: =SUMIFS($BL:$BL,$C:$C,$C27) -> 2365642.5 | BV27: =SUMIFS($BK:$BK,$C:$C,$C27) -> 5593311.1 | BW27: =SUMIFS($AY:$AY,$C:$C,$C27) -> 1989738.4 | BY27: =IF($K27="GEO-GSO",$AK27*Proton_Flare_InsLoss,0)*Q27 -> 178377.78 | BZ27: =IF(AND($K27="GEO-GSO",AL27="FUL"),$AK27*Proton_Flare_InsLoss,0)*$Q27 -> 0 | CA27: =IF(AND($K27="GEO-GSO",AL27="FIID"),$AK27*Proton_Flare_InsLoss,0)*$Q27 -> 178377.78 | CB27: =IF(AND($K27="GEO-GSO",AL27="FIBL"),$AK27*Proton_Flare_InsLoss,0)*$Q27 -> 0 | CC27: =IF($K27="GEO-GSO",(AK27*BG27-BJ27)*Proton_Flare_InsLoss,0)*Q27 -> 151621.11 | CD27: =IF($K27="GEO-GSO",$AK27*Proton_Flare_InsLoss,0)*$Q27*$R27*0.2 -> 0 | CH27: SSL (Space Systems/Loral - Part of Maxar) | CI27: =SUMIFS($AK:$AK,$K:$K,"GEO-GSO",$N:$N,$CH27,$Q:$Q,1) -> 45814678 | CJ27: =SUMIFS($AK:$AK,$K:$K,"GEO-GSO",$N:$N,$CH27,$Q:$Q,1,$AL:$AL,CJ$19) -> 30795155 | CK27: =SUMIFS($AK:$AK,$K:$K,"GEO-GSO",$N:$N,$CH27,$Q:$Q,1,$AL:$AL,CK$19) -> 15019523 | CL27: =SUMIFS($AK:$AK,$K:$K,"GEO-GSO",$N:$N,$CH27,$Q:$Q,1,$AL:$AL,"FIBL") -> 0 | CM27: =SUMIFS($BK:$BK,$K:$K,"GEO-GSO",$N:$N,CH27,$Q:$Q,1) -> 22531337 | CN27: =SUMIFS($AK:$AK,$K:$K,"GEO-GSO",$N:$N,$CH27,$Q:$Q,1,$R:$R,1)*0.2 -> 0 | CR27: =IF(OR($K27="GEO-GSO",$K27="MEO"),$AK27*Generic_Defect_Loss,0)*$Q27*$P27 -> 356755.56 | CS27: =IF(AND(OR($K27="GEO-GSO",$K27="MEO"),$AL27=CS$19),$AK27*Generic_Defect_Loss,0)*$Q27*$P27 -> 0 | CT27: =IF(AND(OR($K27="GEO-GSO",$K27="MEO"),$AL27=CT$19),$AK27*Generic_Defect_Loss,0)*$Q27*$P27 -> 356755.56 | CU27: =IF(AND(OR($K27="GEO-GSO",$K27="MEO"),$AL27="FIBL"),$AK27*Generic_Defect_Loss,0)*$Q27*$P27 -> 0 | CV27: =IF(OR($K27="GEO-GSO",$K27="MEO"),($AK27*BG27-BJ27)*Generic_Defect_Loss,0)*$Q27*$P27 -> 303242.22 | CW27: =IF(OR($K27="GEO-GSO",$K27="MEO"),$AK27*Generic_Defect_Loss,0)*$Q27*$P27*$R27*0.2 -> 0 | CY27: =IF(OR($K27="GEO-GSO",$K27="MEO"),$AK27*Space_Debris_Loss,0)*$Q27*$AE27 -> 178377.78 | CZ27: =IF(AND(OR($K27="GEO-GSO",$K27="MEO"),$AL27=CZ$19),$AK27*Space_Debris_Loss,0)*$Q27*$AE27 -> 0 | DA27: =IF(AND(OR($K27="GEO-GSO",$K27="MEO"),$AL27=DA$19),$AK27*Space_Debris_Loss,0)*$Q27*$AE27 -> 178377.78 | DB27: =IF(AND(OR($K27="GEO-GSO",$K27="MEO"),$AL27="FIBL"),$AK27*Space_Debris_Loss,0)*$Q27*$AE27 -> 0 | DC27: =IF(OR($K27="GEO-GSO",$K27="MEO"),($AK27*BG27-BJ27)*Space_Debris_Loss,0)*$Q27*$AE27 -> 151621.11 | DD27: =IF(OR($K27="GEO-GSO",$K27="MEO"),$AK27*1,0)*$Q27*$AE27*$R27*0.2 -> 0
